Traceback (most recent call last):
  File "C:\Users\matth\PycharmProjects\ExcelParsers\1.0\main.py", line 1000, in load_data_file
    df = pd.read_excel(f'{send_way_to_file()}', index_col=None, sheet_name='Лист1',
  File "C:\Users\matth\AppData\Roaming\Python\Python310\site-packages\pandas\io\excel\_base.py", line 478, in read_excel
    io = ExcelFile(io, storage_options=storage_options, engine=engine)
  File "C:\Users\matth\AppData\Roaming\Python\Python310\site-packages\pandas\io\excel\_base.py", line 1496, in __init__
    ext = inspect_excel_format(
  File "C:\Users\matth\AppData\Roaming\Python\Python310\site-packages\pandas\io\excel\_base.py", line 1371, in inspect_excel_format
    with get_handle(
  File "C:\Users\matth\AppData\Roaming\Python\Python310\site-packages\pandas\io\common.py", line 868, in get_handle
    handle = open(handle, ioargs.mode)
FileNotFoundError: [Errno 2] No such file or directory: ''

During handling of the above exception, another exception occurred:

Traceback (most recent call last):
  File "C:\Users\matth\PycharmProjects\ExcelParsers\1.0\main.py", line 1037, in <module>
    main()
  File "C:\Users\matth\PycharmProjects\ExcelParsers\1.0\main.py", line 14, in main
    load_data_file()
  File "C:\Users\matth\PycharmProjects\ExcelParsers\1.0\main.py", line 1003, in load_data_file
    print('--------------------------------------------------')
OSError: [Errno 22] Invalid argument
